Workbook

Sheet Summary
A1: 07K ZN6 Turbo Swap — Cost Summary
A2: All prices in CAD (USD × 1.42, GBP × 1.85 at Oct 4, 2026), before HST. Low/High = estimate range. WORKING = your actual price where you've entered one, otherwise the midpoint of the estimate. Have = Y lines count $0.
A4: Assumptions
B5: Currency | C5: CAD per unit | D5: Source
B6: CAD | C6: 1 | D6: —
B7: USD | C7: 1.42 | D7: Rate from the Oct 4, 2026 notes. Update.
B8: GBP | C8: 1.85 | D8: Estimate — update before ordering from the UK.
B10: Contingency on unconfirmed lines | C10: 0.25 | D10: Applied only to lines where you have NOT entered an actual price. Falls as you confirm prices.
B11: Gearbox route | C11: RX-8 | D11: RX-8 = RX-8 gearbox + your adapter. ZN6 TL70 = keep the car's gearbox with a custom adapter. Lines tagged for the other route turn orange and drop out.
A13: Totals by system
B14: Group | C14: Low (CAD) | D14: High (CAD) | E14: WORKING (CAD)
B15: Donors | C15: =SUMIFS(BOM!$U$5:$U$247,BOM!$L$5:$L$247,$B15) -> 11995 | D15: =SUMIFS(BOM!$V$5:$V$247,BOM!$L$5:$L$247,$B15) -> 23250 | E15: =SUMIFS(BOM!$I$5:$I$247,BOM!$L$5:$L$247,$B15) -> 17622.5
B16: Engine prep | C16: =SUMIFS(BOM!$U$5:$U$247,BOM!$L$5:$L$247,$B16) -> 1144 | D16: =SUMIFS(BOM!$V$5:$V$247,BOM!$L$5:$L$247,$B16) -> 2874 | E16: =SUMIFS(BOM!$I$5:$I$247,BOM!$L$5:$L$247,$B16) -> 2009
B17: Gearbox: RX-8 | C17: =SUMIFS(BOM!$U$5:$U$247,BOM!$L$5:$L$247,$B17) -> 2260 | D17: =SUMIFS(BOM!$V$5:$V$247,BOM!$L$5:$L$247,$B17) -> 5613 | E17: =SUMIFS(BOM!$I$5:$I$247,BOM!$L$5:$L$247,$B17) -> 3936.5
B18: Gearbox: ZN6 TL70 | C18: =SUMIFS(BOM!$U$5:$U$247,BOM!$L$5:$L$247,$B18) -> 0 | D18: =SUMIFS(BOM!$V$5:$V$247,BOM!$L$5:$L$247,$B18) -> 0 | E18: =SUMIFS(BOM!$I$5:$I$247,BOM!$L$5:$L$247,$B18) -> 0
B19: Driveline | C19: =SUMIFS(BOM!$U$5:$U$247,BOM!$L$5:$L$247,$B19) -> 724 | D19: =SUMIFS(BOM!$V$5:$V$247,BOM!$L$5:$L$247,$B19) -> 1315 | E19: =SUMIFS(BOM!$I$5:$I$247,BOM!$L$5:$L$247,$B19) -> 1019.5
B20: Mounts & chassis | C20: =SUMIFS(BOM!$U$5:$U$247,BOM!$L$5:$L$247,$B20) -> 295 | D20: =SUMIFS(BOM!$V$5:$V$247,BOM!$L$5:$L$247,$B20) -> 895 | E20: =SUMIFS(BOM!$I$5:$I$247,BOM!$L$5:$L$247,$B20) -> 595
B21: Turbo | C21: =SUMIFS(BOM!$U$5:$U$247,BOM!$L$5:$L$247,$B21) -> 4933 | D21: =SUMIFS(BOM!$V$5:$V$247,BOM!$L$5:$L$247,$B21) -> 8511 | E21: =SUMIFS(BOM!$I$5:$I$247,BOM!$L$5:$L$247,$B21) -> 6722
B22: Intake manifold (custom) | C22: =SUMIFS(BOM!$U$5:$U$247,BOM!$L$5:$L$247,$B22) -> 393 | D22: =SUMIFS(BOM!$V$5:$V$247,BOM!$L$5:$L$247,$B22) -> 680 | E22: =SUMIFS(BOM!$I$5:$I$247,BOM!$L$5:$L$247,$B22) -> 536.5
B23: Fuel | C23: =SUMIFS(BOM!$U$5:$U$247,BOM!$L$5:$L$247,$B23) -> 1078 | D23: =SUMIFS(BOM!$V$5:$V$247,BOM!$L$5:$L$247,$B23) -> 2305 | E23: =SUMIFS(BOM!$I$5:$I$247,BOM!$L$5:$L$247,$B23) -> 1691.5
B24: ECU / electronics | C24: =SUMIFS(BOM!$U$5:$U$247,BOM!$L$5:$L$247,$B24) -> 1083 | D24: =SUMIFS(BOM!$V$5:$V$247,BOM!$L$5:$L$247,$B24) -> 3553 | E24: =SUMIFS(BOM!$I$5:$I$247,BOM!$L$5:$L$247,$B24) -> 2318
B25: Cooling | C25: =SUMIFS(BOM!$U$5:$U$247,BOM!$L$5:$L$247,$B25) -> 623 | D25: =SUMIFS(BOM!$V$5:$V$247,BOM!$L$5:$L$247,$B25) -> 1340 | E25: =SUMIFS(BOM!$I$5:$I$247,BOM!$L$5:$L$247,$B25) -> 981.5
B26: Oil system | C26: =SUMIFS(BOM!$U$5:$U$247,BOM!$L$5:$L$247,$B26) -> 482 | D26: =SUMIFS(BOM!$V$5:$V$247,BOM!$L$5:$L$247,$B26) -> 1010 | E26: =SUMIFS(BOM!$I$5:$I$247,BOM!$L$5:$L$247,$B26) -> 746
... B29: Credit | C29: =SUMIFS(BOM!$U$5:$U$247,BOM!$L$5:$L$247,$B29) -> 0 | D29: =SUMIFS(BOM!$V$5:$V$247,BOM!$L$5:$L$247,$B29) -> 0 | E29: =SUMIFS(BOM!$I$5:$I$247,BOM!$L$5:$L$247,$B29) -> 0
A31: Totals by phase
B32: Group | C32: Low (CAD) | D32: High (CAD) | E32: WORKING (CAD)
B33: 0 Donors | C33: =SUMIFS(BOM!$U$5:$U$247,BOM!$S$5:$S$247,$B33) -> 12015 | D33: =SUMIFS(BOM!$V$5:$V$247,BOM!$S$5:$S$247,$B33) -> 23335 | E33: =SUMIFS(BOM!$I$5:$I$247,BOM!$S$5:$S$247,$B33) -> 17675
B34: 1 Bench / run stand | C34: =SUMIFS(BOM!$U$5:$U$247,BOM!$S$5:$S$247,$B34) -> 860 | D34: =SUMIFS(BOM!$V$5:$V$247,BOM!$S$5:$S$247,$B34) -> 1940 | E34: =SUMIFS(BOM!$I$5:$I$247,BOM!$S$5:$S$247,$B34) -> 1400
B35: 2 NA swap | C35: =SUMIFS(BOM!$U$5:$U$247,BOM!$S$5:$S$247,$B35) -> 5635 | D35: =SUMIFS(BOM!$V$5:$V$247,BOM!$S$5:$S$247,$B35) -> 13370 | E35: =SUMIFS(BOM!$I$5:$I$247,BOM!$S$5:$S$247,$B35) -> 9502.5
B36: 3 Turbo | C36: =SUMIFS(BOM!$U$5:$U$247,BOM!$S$5:$S$247,$B36) -> 7190 | D36: =SUMIFS(BOM!$V$5:$V$247,BOM!$S$5:$S$247,$B36) -> 14016 | E36: =SUMIFS(BOM!$I$5:$I$247,BOM!$S$5:$S$247,$B36) -> 10603
B37: Tools | C37: =SUMIFS(BOM!$U$5:$U$247,BOM!$S$5:$S$247,$B37) -> 85 | D37: =SUMIFS(BOM!$V$5:$V$247,BOM!$S$5:$S$247,$B37) -> 495 | E37: =SUMIFS(BOM!$I$5:$I$247,BOM!$S$5:$S$247,$B37) -> 290
A39: Totals by source
B40: Group | C40: Low (CAD) | D40: High (CAD) | E40: WORKING (CAD)
B41: Buy | C41: =SUMIFS(BOM!$U$5:$U$247,BOM!$Q$5:$Q$247,$B41) -> 24758 | D41: =SUMIFS(BOM!$V$5:$V$247,BOM!$Q$5:$Q$247,$B41) -> 50596 | E41: =SUMIFS(BOM!$I$5:$I$247,BOM!$Q$5:$Q$247,$B41) -> 37677
B42: Make | C42: =SUMIFS(BOM!$U$5:$U$247,BOM!$Q$5:$Q$247,$B42) -> 1027 | D42: =SUMIFS(BOM!$V$5:$V$247,BOM!$Q$5:$Q$247,$B42) -> 2560 | E42: =SUMIFS(BOM!$I$5:$I$247,BOM!$Q$5:$Q$247,$B42) -> 1793.5
B43: Have | C43: =SUMIFS(BOM!$U$5:$U$247,BOM!$Q$5:$Q$247,$B43) -> 0 | D43: =SUMIFS(BOM!$V$5:$V$247,BOM!$Q$5:$Q$247,$B43) -> 0 | E43: =SUMIFS(BOM!$I$5:$I$247,BOM!$Q$5:$Q$247,$B43) -> 0
B44: Sell | C44: =SUMIFS(BOM!$U$5:$U$247,BOM!$Q$5:$Q$247,$B44) -> 0 | D44: =SUMIFS(BOM!$V$5:$V$247,BOM!$Q$5:$Q$247,$B44) -> 0 | E44: =SUMIFS(BOM!$I$5:$I$247,BOM!$Q$5:$Q$247,$B44) -> 0
A46: Budget
B47: Group | C47: Low (CAD) | D47: High (CAD) | E47: WORKING (CAD)
B48: Donor car (D01) | C48: =SUMIFS(BOM!$U$5:$U$247,BOM!$A$5:$A$247,"D01") -> 11500 | D48: =SUMIFS(BOM!$V$5:$V$247,BOM!$A$5:$A$247,"D01") -> 21000 | E48: =SUMIFS(BOM!$I$5:$I$247,BOM!$A$5:$A$247,"D01") -> 16250
...

Sheet BOM
A1: 07K ZN6 Turbo Swap — Detailed BOM
A2: Fill the blue columns: Have? (Y = own it → $0), Make? (Y = you make it), MY cost (real price, CAD → overrides the estimate). Columns L–X (notes, vendor, phase, links) are hidden — click the + above column L to show them. Use the filter arrows to view one System at a time.
A4: ID | B4: Part | C4: Qty | D4: Est. low | E4: Est. high | F4: Have? | G4: Make? | H4: MY cost | I4: Working (CAD) | J4: Status | K4: Incl. | L4: System | M4: Sub-assembly | N4: Spec / notes | O4: Unit | P4: Cur | Q4: Source | R4: Vendor / ref | S4: Phase | T4: Route | U4: Ext low (CAD) | V4: Ext high (CAD) | W4: Basis | X4: Link
A5: D01 | B5: ZN6 FR-S / BRZ / 86, manual, RUNNING | C5: 1 | D5: 11500 | E5: 21000 | F5: N | G5: N | I5: =IF(AND($K5="Y",$F5<>"Y",OR($T5="",$T5=Summary!$C$11)),$C5*IF($H5<>"",$H5,($D5+$E5)/2)*INDEX(Summary!$C$6:$C$8,MATCH($P5,Summary!$B$6:$B$8,0)),0) -> 16250 | J5: Need | K5: Y | L5: Donors | M5: Car | N5: Must run so the stock CAN bus can be logged before the FA20 comes out. Clean shell > low km. | O5: ea | P5: CAD | Q5: Buy | R5: Kijiji / CarGurus | S5: 0 Donors | U5: =IF(AND($K5="Y",$F5<>"Y",OR($T5="",$T5=Summary!$C$11)),$C5*IF($H5<>"",$H5,$D5)*INDEX(Summary!$C$6:$C$8,MATCH($P5,Summary!$B$6:$B$8,0)),0) -> 11500 | V5: =IF(AND($K5="Y",$F5<>"Y",OR($T5="",$T5=Summary!$C$11)),$C5*IF($H5<>"",$H5,$E5)*INDEX(Summary!$C$6:$C$8,MATCH($P5,Summary!$B$6:$B$8,0)),0) -> 21000 | W5: Notes | X5: https://www.cargurus.ca/Cars/l-Used-Scion-FR-S-Toronto-d2140_L414276
A6: D02 | B6: 07K 2.5 engine, 2005–08 (ME7.1.1, MAF), with ECU + engine harness | C6: 1 | D6: 425 | E6: 1635 | F6: N | G6: N | I6: =IF(AND($K6="Y",$F6<>"Y",OR($T6="",$T6=Summary!$C$11)),$C6*IF($H6<>"",$H6,($D6+$E6)/2)*INDEX(Summary!$C$6:$C$8,MATCH($P6,Summary!$B$6:$B$8,0)),0) -> 1030 | J6: Need | K6: Y | L6: Donors | M6: Engine | N6: Confirm it comes with ECU, harness, coils, injectors, alternator, intake manifold, oil pan, flywheel-end cover. 6- vs 8-bolt crank flange. | O6: ea | P6: CAD | Q6: Buy | R6: eBay / junkyard / Marketplace | S6: 0 Donors | U6: =IF(AND($K6="Y",$F6<>"Y",OR($T6="",$T6=Summary!$C$11)),$C6*IF($H6<>"",$H6,$D6)*INDEX(Summary!$C$6:$C$8,MATCH($P6,Summary!$B$6:$B$8,0)),0) -> 425 | V6: =IF(AND($K6="Y",$F6<>"Y",OR($T6="",$T6=Summary!$C$11)),$C6*IF($H6<>"",$H6,$E6)*INDEX(Summary!$C$6:$C$8,MATCH($P6,Summary!$B$6:$B$8,0)),0) -> 1635 | W6: Notes | X6: https://www.ebay.com/itm/355614546913
A7: D03 | B7: Engine freight / pickup | C7: 1 | D7: 0 | E7: 400 | F7: N | G7: N | I7: =IF(AND($K7="Y",$F7<>"Y",OR($T7="",$T7=Summary!$C$11)),$C7*IF($H7<>"",$H7,($D7+$E7)/2)*INDEX(Summary!$C$6:$C$8,MATCH($P7,Summary!$B$6:$B$8,0)),0) -> 200 | J7: Need | K7: Y | L7: Donors | M7: Engine | N7: Pallet freight or a trailer trip. | O7: ea | P7: CAD | Q7: Buy | R7: — | S7: 0 Donors | U7: =IF(AND($K7="Y",$F7<>"Y",OR($T7="",$T7=Summary!$C$11)),$C7*IF($H7<>"",$H7,$D7)*INDEX(Summary!$C$6:$C$8,MATCH($P7,Summary!$B$6:$B$8,0)),0) -> 0 | V7: =IF(AND($K7="Y",$F7<>"Y",OR($T7="",$T7=Summary!$C$11)),$C7*IF($H7<>"",$H7,$E7)*INDEX(Summary!$C$6:$C$8,MATCH($P7,Summary!$B$6:$B$8,0)),0) -> 400 | W7: Estimate
A8: D04 | B8: Junk 02J bellhousing (VW 4-cyl pattern) | C8: 1 | D8: 70 | E8: 215 | F8: N | G8: N | I8: =IF(AND($K8="Y",$F8<>"Y",OR($T8="",$T8=Summary!$C$11)),$C8*IF($H8<>"",$H8,($D8+$E8)/2)*INDEX(Summary!$C$6:$C$8,MATCH($P8,Summary!$B$6:$B$8,0)),0) -> 142.5 | J8: Need | K8: Y | L8: Donors | M8: Measurement | N8: Only for measuring the 07K bolt/dowel pattern on the mill. Resell after. | O8: ea | P8: CAD | Q8: Buy | R8: Junkyard | S8: 0 Donors | U8: =IF(AND($K8="Y",$F8<>"Y",OR($T8="",$T8=Summary!$C$11)),$C8*IF($H8<>"",$H8,$D8)*INDEX(Summary!$C$6:$C$8,MATCH($P8,Summary!$B$6:$B$8,0)),0) -> 70 | V8: =IF(AND($K8="Y",$F8<>"Y",OR($T8="",$T8=Summary!$C$11)),$C8*IF($H8<>"",$H8,$E8)*INDEX(Summary!$C$6:$C$8,MATCH($P8,Summary!$B$6:$B$8,0)),0) -> 215 | W8: Estimate
A9: D05 | B9: Spare 07K cylinder head (scrap) — manifold welding fixture | C9: 1 | D9: 140 | E9: 425 | F9: N | G9: N | I9: =IF(AND($K9="Y",$F9<>"Y",OR($T9="",$T9=Summary!$C$11)),$C9*IF($H9<>"",$H9,($D9+$E9)/2)*INDEX(Summary!$C$6:$C$8,MATCH($P9,Summary!$B$6:$B$8,0)),0) -> 0 | J9: Optional | K9: N | L9: Donors | M9: Measurement | N9: Optional. A 1/2 in steel plate drilled to the port pattern also works. | O9: ea | P9: CAD | Q9: Buy | R9: Junkyard | S9: 0 Donors | U9: =IF(AND($K9="Y",$F9<>"Y",OR($T9="",$T9=Summary!$C$11)),$C9*IF($H9<>"",$H9,$D9)*INDEX(Summary!$C$6:$C$8,MATCH($P9,Summary!$B$6:$B$8,0)),0) -> 0 | V9: =IF(AND($K9="Y",$F9<>"Y",OR($T9="",$T9=Summary!$C$11)),$C9*IF($H9<>"",$H9,$E9)*INDEX(Summary!$C$6:$C$8,MATCH($P9,Summary!$B$6:$B$8,0)),0) -> 0 | W9: Estimate
A10: E01 | B10: Rear main seal (crank, flywheel end) | C10: 1 | D10: 30 | E10: 65 | F10: N | G10: N | I10: =IF(AND($K10="Y",$F10<>"Y",OR($T10="",$T10=Summary!$C$11)),$C10*IF($H10<>"",$H10,($D10+$E10)/2)*INDEX(Summary!$C$6:$C$8,MATCH($P10,Summary!$B$6:$B$8,0)),0) -> 47.5 | J10: Need | K10: Y | L10: Engine prep | M10: Seals | N10: Do it while the flywheel is off — it's behind the adapter plate forever after. | O10: ea | P10: CAD | Q10: Buy | R10: ECS / Das Parts | S10: 2 NA swap | U10: =IF(AND($K10="Y",$F10<>"Y",OR($T10="",$T10=Summary!$C$11)),$C10*IF($H10<>"",$H10,$D10)*INDEX(Summary!$C$6:$C$8,MATCH($P10,Summary!$B$6:$B$8,0)),0) -> 30 | V10: =IF(AND($K10="Y",$F10<>"Y",OR($T10="",$T10=Summary!$C$11)),$C10*IF($H10<>"",$H10,$E10)*INDEX(Summary!$C$6:$C$8,MATCH($P10,Summary!$B$6:$B$8,0)),0) -> 65 | W10: Estimate
A11: E02 | B11: Front crank seal | C11: 1 | D11: 14 | E11: 35 | F11: N | G11: N | I11: =IF(AND($K11="Y",$F11<>"Y",OR($T11="",$T11=Summary!$C$11)),$C11*IF($H11<>"",$H11,($D11+$E11)/2)*INDEX(Summary!$C$6:$C$8,MATCH($P11,Summary!$B$6:$B$8,0)),0) -> 24.5 | J11: Need | K11: Y | L11: Engine prep | M11: Seals | O11: ea | P11: CAD | Q11: Buy | R11: ECS / Das Parts | S11: 2 NA swap | U11: =IF(AND($K11="Y",$F11<>"Y",OR($T11="",$T11=Summary!$C$11)),$C11*IF($H11<>"",$H11,$D11)*INDEX(Summary!$C$6:$C$8,MATCH($P11,Summary!$B$6:$B$8,0)),0) -> 14 | V11: =IF(AND($K11="Y",$F11<>"Y",OR($T11="",$T11=Summary!$C$11)),$C11*IF($H11<>"",$H11,$E11)*INDEX(Summary!$C$6:$C$8,MATCH($P11,Summary!$B$6:$B$8,0)),0) -> 35 | W11: Estimate
A12: E03 | B12: Valve cover gasket | C12: 1 | D12: 35 | E12: 70 | F12: N | G12: N | I12: =IF(AND($K12="Y",$F12<>"Y",OR($T12="",$T12=Summary!$C$11)),$C12*IF($H12<>"",$H12,($D12+$E12)/2)*INDEX(Summary!$C$6:$C$8,MATCH($P12,Summary!$B$6:$B$8,0)),0) -> 52.5 | J12: Need | K12: Y | L12: Engine prep | M12: Seals | O12: ea | P12: CAD | Q12: Buy | R12: ECS / Das Parts | S12: 2 NA swap | U12: =IF(AND($K12="Y",$F12<>"Y",OR($T12="",$T12=Summary!$C$11)),$C12*IF($H12<>"",$H12,$D12)*INDEX(Summary!$C$6:$C$8,MATCH($P12,Summary!$B$6:$B$8,0)),0) -> 35 | V12: =IF(AND($K12="Y",$F12<>"Y",OR($T12="",$T12=Summary!$C$11)),$C12*IF($H12<>"",$H12,$E12)*INDEX(Summary!$C$6:$C$8,MATCH($P12,Summary!$B$6:$B$8,0)),0) -> 70 | W12: Estimate
A13: E04 | B13: Cam adjuster / cam plug seals | C13: 1 | D13: 20 | E13: 55 | F13: N | G13: N | I13: =IF(AND($K13="Y",$F13<>"Y",OR($T13="",$T13=Summary!$C$11)),$C13*IF($H13<>"",$H13,($D13+$E13)/2)*INDEX(Summary!$C$6:$C$8,MATCH($P13,Summary!$B$6:$B$8,0)),0) -> 37.5 | J13: Need | K13: Y | L13: Engine prep | M13: Seals | N13: Common 07K leak point. | O13: set | P13: CAD | Q13: Buy | R13: ECS / Das Parts | S13: 2 NA swap | U13: =IF(AND($K13="Y",$F13<>"Y",OR($T13="",$T13=Summary!$C$11)),$C13*IF($H13<>"",$H13,$D13)*INDEX(Summary!$C$6:$C$8,MATCH($P13,Summary!$B$6:$B$8,0)),0) -> 20 | V13: =IF(AND($K13="Y",$F13<>"Y",OR($T13="",$T13=Summary!$C$11)),$C13*IF($H13<>"",$H13,$E13)*INDEX(Summary!$C$6:$C$8,MATCH($P13,Summary!$B$6:$B$8,0)),0) -> 55 | W13: Estimate
A14: E05 | B14: Oil filter housing gasket / O-rings | C14: 1 | D14: 14 | E14: 35 | F14: N | G14: N | I14: =IF(AND($K14="Y",$F14<>"Y",OR($T14="",$T14=Summary!$C$11)),$C14*IF($H14<>"",$H14,($D14+$E14)/2)*INDEX(Summary!$C$6:$C$8,MATCH($P14,Summary!$B$6:$B$8,0)),0) -> 24.5 | J14: Need | K14: Y | L14: Engine prep | M14: Seals | O14: set | P14: CAD | Q14: Buy | R14: ECS / Das Parts | S14: 2 NA swap | U14: =IF(AND($K14="Y",$F14<>"Y",OR($T14="",$T14=Summary!$C$11)),$C14*IF($H14<>"",$H14,$D14)*INDEX(Summary!$C$6:$C$8,MATCH($P14,Summary!$B$6:$B$8,0)),0) -> 14 | V14: =IF(AND($K14="Y",$F14<>"Y",OR($T14="",$T14=Summary!$C$11)),$C14*IF($H14<>"",$H14,$E14)*INDEX(Summary!$C$6:$C$8,MATCH($P14,Summary!$B$6:$B$8,0)),0) -> 35 | W14: Estimate
A15: E06 | B15: Intake manifold gaskets (5) | C15: 1 | D15: 20 | E15: 50 | F15: N | G15: N | I15: =IF(AND($K15="Y",$F15<>"Y",OR($T15="",$T15=Summary!$C$11)),$C15*IF($H15<>"",$H15,($D15+$E15)/2)*INDEX(Summary!$C$6:$C$8,MATCH($P15,Summary!$B$6:$B$8,0)),0) -> 35 | J15: Need | K15: Y | L15: Engine prep | M15: Seals | O15: set | P15: CAD | Q15: Buy | R15: ECS / Das Parts | S15: 2 NA swap | U15: =IF(AND($K15="Y",$F15<>"Y",OR($T15="",$T15=Summary!$C$11)),$C15*IF($H15<>"",$H15,$D15)*INDEX(Summary!$C$6:$C$8,MATCH($P15,Summary!$B$6:$B$8,0)),0) -> 20 | V15: =IF(AND($K15="Y",$F15<>"Y",OR($T15="",$T15=Summary!$C$11)),$C15*IF($H15<>"",$H15,$E15)*INDEX(Summary!$C$6:$C$8,MATCH($P15,Summary!$B$6:$B$8,0)),0) -> 50 | W15: Estimate
A16: E07 | B16: Exhaust manifold gasket (OEM, for your custom flange) | C16: 1 | D16: 14 | E16: 35 | F16: N | G16: N | I16: =IF(AND($K16="Y",$F16<>"Y",OR($T16="",$T16=Summary!$C$11)),$C16*IF($H16<>"",$H16,($D16+$E16)/2)*INDEX(Summary!$C$6:$C$8,MATCH($P16,Summary!$B$6:$B$8,0)),0) -> 24.5 | J16: Need | K16: Y | L16: Engine prep | M16: Seals | O16: ea | P16: CAD | Q16: Buy | R16: ECS / Das Parts | S16: 3 Turbo | U16: =IF(AND($K16="Y",$F16<>"Y",OR($T16="",$T16=Summary!$C$11)),$C16*IF($H16<>"",$H16,$D16)*INDEX(Summary!$C$6:$C$8,MATCH($P16,Summary!$B$6:$B$8,0)),0) -> 14 | V16: =IF(AND($K16="Y",$F16<>"Y",OR($T16="",$T16=Summary!$C$11)),$C16*IF($H16<>"",$H16,$E16)*INDEX(Summary!$C$6:$C$8,MATCH($P16,Summary!$B$6:$B$8,0)),0) -> 35 | W16: Estimate
A17: E08 | B17: RTV sealant (oil pan, timing cover, upper pan) | C17: 2 | D17: 17 | E17: 35 | F17: N | G17: N | I17: =IF(AND($K17="Y",$F17<>"Y",OR($T17="",$T17=Summary!$C$11)),$C17*IF($H17<>"",$H17,($D17+$E17)/2)*INDEX(Summary!$C$6:$C$8,MATCH($P17,Summary!$B$6:$B$8,0)),0) -> 52 | J17: Need | K17: Y | L17: Engine prep | M17: Seals | N17: VW D176404A2 or Permatex Ultra Grey. 2 tubes. | O17: ea | P17: CAD | Q17: Buy | R17: Any | S17: 2 NA swap | U17: =IF(AND($K17="Y",$F17<>"Y",OR($T17="",$T17=Summary!$C$11)),$C17*IF($H17<>"",$H17,$D17)*INDEX(Summary!$C$6:$C$8,MATCH($P17,Summary!$B$6:$B$8,0)),0) -> 34 | V17: =IF(AND($K17="Y",$F17<>"Y",OR($T17="",$T17=Summary!$C$11)),$C17*IF($H17<>"",$H17,$E17)*INDEX(Summary!$C$6:$C$8,MATCH($P17,Summary!$B$6:$B$8,0)),0) -> 70 | W17: Estimate
A18: E09 | B18: Water pump | C18: 1 | D18: 85 | E18: 170 | F18: N | G18: N | I18: =IF(AND($K18="Y",$F18<>"Y",OR($T18="",$T18=Summary!$C$11)),$C18*IF($H18<>"",$H18,($D18+$E18)/2)*INDEX(Summary!$C$6:$C$8,MATCH($P18,Summary!$B$6:$B$8,0)),0) -> 127.5 | J18: Need | K18: Y | L18: Engine prep | M18: Cooling | O18: ea | P18: CAD | Q18: Buy | R18: ECS / Das Parts | S18: 2 NA swap | U18: =IF(AND($K18="Y",$F18<>"Y",OR($T18="",$T18=Summary!$C$11)),$C18*IF($H18<>"",$H18,$D18)*INDEX(Summary!$C$6:$C$8,MATCH($P18,Summary!$B$6:$B$8,0)),0) -> 85 | V18: =IF(AND($K18="Y",$F18<>"Y",OR($T18="",$T18=Summary!$C$11)),$C18*IF($H18<>"",$H18,$E18)*INDEX(Summary!$C$6:$C$8,MATCH($P18,Summary!$B$6:$B$8,0)),0) -> 170 | W18: Estimate
A19: E10 | B19: Thermostat + housing O-ring | C19: 1 | D19: 30 | E19: 65 | F19: N | G19: N | I19: =IF(AND($K19="Y",$F19<>"Y",OR($T19="",$T19=Summary!$C$11)),$C19*IF($H19<>"",$H19,($D19+$E19)/2)*INDEX(Summary!$C$6:$C$8,MATCH($P19,Summary!$B$6:$B$8,0)),0) -> 47.5 | J19: Need | K19: Y | L19: Engine prep | M19: Cooling | O19: ea | P19: CAD | Q19: Buy | R19: ECS / Das Parts | S19: 2 NA swap | U19: =IF(AND($K19="Y",$F19<>"Y",OR($T19="",$T19=Summary!$C$11)),$C19*IF($H19<>"",$H19,$D19)*INDEX(Summary!$C$6:$C$8,MATCH($P19,Summary!$B$6:$B$8,0)),0) -> 30 | V19: =IF(AND($K19="Y",$F19<>"Y",OR($T19="",$T19=Summary!$C$11)),$C19*IF($H19<>"",$H19,$E19)*INDEX(Summary!$C$6:$C$8,MATCH($P19,Summary!$B$6:$B$8,0)),0) -> 65 | W19: Estimate
A20: E11 | B20: Timing chain kit (chains, guides, tensioners) — inspect first | C20: 1 | D20: 0 | E20: 570 | F20: N | G20: N | I20: =IF(AND($K20="Y",$F20<>"Y",OR($T20="",$T20=Summary!$C$11)),$C20*IF($H20<>"",$H20,($D20+$E20)/2)*INDEX(Summary!$C$6:$C$8,MATCH($P20,Summary!$B$6:$B$8,0)),0) -> 285 | J20: To decide | K20: Y | L20: Engine prep | M20: Timing | N20: Chains are on the flywheel end; engine-out is the only time to do this. $0 if they look fine. | O20: kit | P20: CAD | Q20: Buy | R20: ECS / Das Parts | S20: 2 NA swap | U20: =IF(AND($K20="Y",$F20<>"Y",OR($T20="",$T20=Summary!$C$11)),$C20*IF($H20<>"",$H20,$D20)*INDEX(Summary!$C$6:$C$8,MATCH($P20,Summary!$B$6:$B$8,0)),0) -> 0 | V20: =IF(AND($K20="Y",$F20<>"Y",OR($T20="",$T20=Summary!$C$11)),$C20*IF($H20<>"",$H20,$E20)*INDEX(Summary!$C$6:$C$8,MATCH($P20,Summary!$B$6:$B$8,0)),0) -> 570 | W20: Estimate
A21: E12 | B21: Timing cover seal (crank side) + bolts | C21: 1 | D21: 14 | E21: 45 | F21: N | G21: N | I21: =IF(AND($K21="Y",$F21<>"Y",OR($T21="",$T21=Summary!$C$11)),$C21*IF($H21<>"",$H21,($D21+$E21)/2)*INDEX(Summary!$C$6:$C$8,MATCH($P21,Summary!$B$6:$B$8,0)),0) -> 29.5 | J21: Need | K21: Y | L21: Engine prep | M21: Timing | O21: set | P21: CAD | Q21: Buy | R21: ECS / Das Parts | S21: 2 NA swap | U21: =IF(AND($K21="Y",$F21<>"Y",OR($T21="",$T21=Summary!$C$11)),$C21*IF($H21<>"",$H21,$D21)*INDEX(Summary!$C$6:$C$8,MATCH($P21,Summary!$B$6:$B$8,0)),0) -> 14 | V21: =IF(AND($K21="Y",$F21<>"Y",OR($T21="",$T21=Summary!$C$11)),$C21*IF($H21<>"",$H21,$E21)*INDEX(Summary!$C$6:$C$8,MATCH($P21,Summary!$B$6:$B$8,0)),0) -> 45 | W21: Estimate
A22: E13 | B22: Oil filter (cartridge) | C22: 2 | D22: 11 | E22: 20 | F22: N | G22: N | I22: =IF(AND($K22="Y",$F22<>"Y",OR($T22="",$T22=Summary!$C$11)),$C22*IF($H22<>"",$H22,($D22+$E22)/2)*INDEX(Summary!$C$6:$C$8,MATCH($P22,Summary!$B$6:$B$8,0)),0) -> 31 | J22: Need | K22: Y | L22: Engine prep | M22: Service | N22: One for the first start, one for the 500 km change. | O22: ea | P22: CAD | Q22: Buy | R22: Any | S22: 2 NA swap | U22: =IF(AND($K22="Y",$F22<>"Y",OR($T22="",$T22=Summary!$C$11)),$C22*IF($H22<>"",$H22,$D22)*INDEX(Summary!$C$6:$C$8,MATCH($P22,Summary!$B$6:$B$8,0)),0) -> 22 | V22: =IF(AND($K22="Y",$F22<>"Y",OR($T22="",$T22=Summary!$C$11)),$C22*IF($H22<>"",$H22,$E22)*INDEX(Summary!$C$6:$C$8,MATCH($P22,Summary!$B$6:$B$8,0)),0) -> 40 | W22: Estimate
A23: E14 | B23: Engine oil 5W-40 (6 L) | C23: 2 | D23: 50 | E23: 85 | F23: N | G23: N | I23: =IF(AND($K23="Y",$F23<>"Y",OR($T23="",$T23=Summary!$C$11)),$C23*IF($H23<>"",$H23,($D23+$E23)/2)*INDEX(Summary!$C$6:$C$8,MATCH($P23,Summary!$B$6:$B$8,0)),0) -> 135 | J23: Need | K23: Y | L23: Engine prep | M23: Service | N23: Two fills: run stand + first change. | O23: fill | P23: CAD | Q23: Buy | R23: Any | S23: 1 Bench / run stand | U23: =IF(AND($K23="Y",$F23<>"Y",OR($T23="",$T23=Summary!$C$11)),$C23*IF($H23<>"",$H23,$D23)*INDEX(Summary!$C$6:$C$8,MATCH($P23,Summary!$B$6:$B$8,0)),0) -> 100 | V23: =IF(AND($K23="Y",$F23<>"Y",OR($T23="",$T23=Summary!$C$11)),$C23*IF($H23<>"",$H23,$E23)*INDEX(Summary!$C$6:$C$8,MATCH($P23,Summary!$B$6:$B$8,0)),0) -> 170 | W23: Estimate
A24: E15 | B24: Spark plugs (5), one step colder for turbo | C24: 5 | D24: 9 | E24: 17 | F24: N | G24: N | I24: =IF(AND($K24="Y",$F24<>"Y",OR($T24="",$T24=Summary!$C$11)),$C24*IF($H24<>"",$H24,($D24+$E24)/2)*INDEX(Summary!$C$6:$C$8,MATCH($P24,Summary!$B$6:$B$8,0)),0) -> 65 | J24: Need | K24: Y | L24: Engine prep | M24: Service | N24: NGK BKR7E-style for boost. | O24: ea | P24: CAD | Q24: Buy | R24: Any | S24: 2 NA swap | U24: =IF(AND($K24="Y",$F24<>"Y",OR($T24="",$T24=Summary!$C$11)),$C24*IF($H24<>"",$H24,$D24)*INDEX(Summary!$C$6:$C$8,MATCH($P24,Summary!$B$6:$B$8,0)),0) -> 45 | V24: =IF(AND($K24="Y",$F24<>"Y",OR($T24="",$T24=Summary!$C$11)),$C24*IF($H24<>"",$H24,$E24)*INDEX(Summary!$C$6:$C$8,MATCH($P24,Summary!$B$6:$B$8,0)),0) -> 85 | W24: Estimate
A25: E16 | B25: Ignition coils (5) | C25: 5 | D25: 30 | E25: 55 | F25: N | G25: N | I25: =IF(AND($K25="Y",$F25<>"Y",OR($T25="",$T25=Summary!$C$11)),$C25*IF($H25<>"",$H25,($D25+$E25)/2)*INDEX(Summary!$C$6:$C$8,MATCH($P25,Summary!$B$6:$B$8,0)),0) -> 212.5 | J25: To decide | K25: Y | L25: Engine prep | M25: Service | N25: Usually come with the engine. Set Have = Y if they do. | O25: ea | P25: CAD | Q25: Buy | R25: ECS / junkyard | S25: 2 NA swap | U25: =IF(AND($K25="Y",$F25<>"Y",OR($T25="",$T25=Summary!$C$11)),$C25*IF($H25<>"",$H25,$D25)*INDEX(Summary!$C$6:$C$8,MATCH($P25,Summary!$B$6:$B$8,0)),0) -> 150 | V25: =IF(AND($K25="Y",$F25<>"Y",OR($T25="",$T25=Summary!$C$11)),$C25*IF($H25<>"",$H25,$E25)*INDEX(Summary!$C$6:$C$8,MATCH($P25,Summary!$B$6:$B$8,0)),0) -> 275 | W25: Estimate
A26: E17 | B26: Serpentine belt + tensioner | C26: 1 | D26: 55 | E26: 140 | F26: N | G26: N | I26: =IF(AND($K26="Y",$F26<>"Y",OR($T26="",$T26=Summary!$C$11)),$C26*IF($H26<>"",$H26,($D26+$E26)/2)*INDEX(Summary!$C$6:$C$8,MATCH($P26,Summary!$B$6:$B$8,0)),0) -> 97.5 | J26: Need | K26: Y | L26: Engine prep | M26: Service | N26: Belt length changes if you delete A/C or move the alternator. | O26: set | P26: CAD | Q26: Buy | R26: ECS / Das Parts | S26: 2 NA swap | U26: =IF(AND($K26="Y",$F26<>"Y",OR($T26="",$T26=Summary!$C$11)),$C26*IF($H26<>"",$H26,$D26)*INDEX(Summary!$C$6:$C$8,MATCH($P26,Summary!$B$6:$B$8,0)),0) -> 55 | V26: =IF(AND($K26="Y",$F26<>"Y",OR($T26="",$T26=Summary!$C$11)),$C26*IF($H26<>"",$H26,$E26)*INDEX(Summary!$C$6:$C$8,MATCH($P26,Summary!$B$6:$B$8,0)),0) -> 140 | W26: Estimate
A27: E18 | B27: SAI (secondary air) block-off plates + gaskets | C27: 1 | D27: 30 | E27: 85 | F27: N | G27: N | I27: =IF(AND($K27="Y",$F27<>"Y",OR($T27="",$T27=Summary!$C$11)),$C27*IF($H27<>"",$H27,($D27+$E27)/2)*INDEX(Summary!$C$6:$C$8,MATCH($P27,Summary!$B$6:$B$8,0)),0) -> 57.5 | J27: Need | K27: Y | L27: Engine prep | M27: Deletes | N27: Software delete is in the RevMap file; plates seal the ports. | O27: set | P27: CAD | Q27: Buy | R27: Various | S27: 2 NA swap | U27: =IF(AND($K27="Y",$F27<>"Y",OR($T27="",$T27=Summary!$C$11)),$C27*IF($H27<>"",$H27,$D27)*INDEX(Summary!$C$6:$C$8,MATCH($P27,Summary!$B$6:$B$8,0)),0) -> 30 | V27: =IF(AND($K27="Y",$F27<>"Y",OR($T27="",$T27=Summary!$C$11)),$C27*IF($H27<>"",$H27,$E27)*INDEX(Summary!$C$6:$C$8,MATCH($P27,Summary!$B$6:$B$8,0)),0) -> 85 | W27: Estimate
A28: E19 | B28: Vacuum pump block-off — MAKE (6061 round bar 3 in × 2 in + O-ring) | C28: 1 | D28: 14 | E28: 35 | F28: N | G28: Y | I28: =IF(AND($K28="Y",$F28<>"Y",OR($T28="",$T28=Summary!$C$11)),$C28*IF($H28<>"",$H28,($D28+$E28)/2)*INDEX(Summary!$C$6:$C$8,MATCH($P28,Summary!$B$6:$B$8,0)),0) -> 0 | J28: Optional | K28: N | L28: Engine prep | M28: Deletes | N28: Flange + collar into the pump bore, O-ring sealed. Only if the pump hits the clutch setup. | O28: ea | P28: CAD | Q28: Make | R28: Metal supplier | S28: 2 NA swap | U28: =IF(AND($K28="Y",$F28<>"Y",OR($T28="",$T28=Summary!$C$11)),$C28*IF($H28<>"",$H28,$D28)*INDEX(Summary!$C$6:$C$8,MATCH($P28,Summary!$B$6:$B$8,0)),0) -> 0 | V28: =IF(AND($K28="Y",$F28<>"Y",OR($T28="",$T28=Summary!$C$11)),$C28*IF($H28<>"",$H28,$E28)*INDEX(Summary!$C$6:$C$8,MATCH($P28,Summary!$B$6:$B$8,0)),0) -> 0 | W28: Estimate | X28: https://performancebyie.com/products/ie-vacuum-pump-blockoff-vw-25l-5cyl
A29: E20 | B29: Vacuum pump O-ring (if keeping the pump) | C29: 1 | D29: 7 | E29: 14 | F29: N | G29: N | I29: =IF(AND($K29="Y",$F29<>"Y",OR($T29="",$T29=Summary!$C$11)),$C29*IF($H29<>"",$H29,($D29+$E29)/2)*INDEX(Summary!$C$6:$C$8,MATCH($P29,Summary!$B$6:$B$8,0)),0) -> 10.5 | J29: Need | K29: Y | L29: Engine prep | M29: Deletes | O29: ea | P29: CAD | Q29: Buy | R29: ECS | S29: 2 NA swap | U29: =IF(AND($K29="Y",$F29<>"Y",OR($T29="",$T29=Summary!$C$11)),$C29*IF($H29<>"",$H29,$D29)*INDEX(Summary!$C$6:$C$8,MATCH($P29,Summary!$B$6:$B$8,0)),0) -> 7 | V29: =IF(AND($K29="Y",$F29<>"Y",OR($T29="",$T29=Summary!$C$11)),$C29*IF($H29<>"",$H29,$E29)*INDEX(Summary!$C$6:$C$8,MATCH($P29,Summary!$B$6:$B$8,0)),0) -> 14 | W29: Estimate
A30: E21 | B30: Oil catch can + 2 hoses + fittings (PCV) | C30: 1 | D30: 55 | E30: 170 | F30: N | G30: N | I30: =IF(AND($K30="Y",$F30<>"Y",OR($T30="",$T30=Summary!$C$11)),$C30*IF($H30<>"",$H30,($D30+$E30)/2)*INDEX(Summary!$C$6:$C$8,MATCH($P30,Summary!$B$6:$B$8,0)),0) -> 112.5 | J30: Need | K30: Y | L30: Engine prep | M30: Breather | N30: Turbo engines push more blow-by; keep oil out of the intercooler. | O30: ea | P30: CAD | Q30: Buy | R30: Various | S30: 3 Turbo | U30: =IF(AND($K30="Y",$F30<>"Y",OR($T30="",$T30=Summary!$C$11)),$C30*IF($H30<>"",$H30,$D30)*INDEX(Summary!$C$6:$C$8,MATCH($P30,Summary!$B$6:$B$8,0)),0) -> 55 | V30: =IF(AND($K30="Y",$F30<>"Y",OR($T30="",$T30=Summary!$C$11)),$C30*IF($H30<>"",$H30,$E30)*INDEX(Summary!$C$6:$C$8,MATCH($P30,Summary!$B$6:$B$8,0)),0) -> 170 | W30: Estimate
A31: E22 | B31: Head gasket (MLS, OEM) | C31: 1 | D31: 85 | E31: 170 | F31: N | G31: N | I31: =IF(AND($K31="Y",$F31<>"Y",OR($T31="",$T31=Summary!$C$11)),$C31*IF($H31<>"",$H31,($D31+$E31)/2)*INDEX(Summary!$C$6:$C$8,MATCH($P31,Summary!$B$6:$B$8,0)),0) -> 127.5 | J31: Need | K31: Y | L31: Engine prep | M31: Head | N31: Turbo phase, or if the head comes off for inspection. | O31: ea | P31: CAD | Q31: Buy | R31: ECS / Das Parts | S31: 3 Turbo | U31: =IF(AND($K31="Y",$F31<>"Y",OR($T31="",$T31=Summary!$C$11)),$C31*IF($H31<>"",$H31,$D31)*INDEX(Summary!$C$6:$C$8,MATCH($P31,Summary!$B$6:$B$8,0)),0) -> 85 | V31: =IF(AND($K31="Y",$F31<>"Y",OR($T31="",$T31=Summary!$C$11)),$C31*IF($H31<>"",$H31,$E31)*INDEX(Summary!$C$6:$C$8,MATCH($P31,Summary!$B$6:$B$8,0)),0) -> 170 | W31: Estimate
A32: E23 | B32: ARP head studs, 07K | C32: 1 | D32: 255 | E32: 400 | F32: N | G32: N | I32: =IF(AND($K32="Y",$F32<>"Y",OR($T32="",$T32=Summary!$C$11)),$C32*IF($H32<>"",$H32,($D32+$E32)/2)*INDEX(Summary!$C$6:$C$8,MATCH($P32,Summary!$B$6:$B$8,0)),0) -> 327.5 | J32: Need | K32: Y | L32: Engine prep | M32: Head | O32: kit | P32: CAD | Q32: Buy | R32: ARP / 034 | S32: 3 Turbo | U32: =IF(AND($K32="Y",$F32<>"Y",OR($T32="",$T32=Summary!$C$11)),$C32*IF($H32<>"",$H32,$D32)*INDEX(Summary!$C$6:$C$8,MATCH($P32,Summary!$B$6:$B$8,0)),0) -> 255 | V32: =IF(AND($K32="Y",$F32<>"Y",OR($T32="",$T32=Summary!$C$11)),$C32*IF($H32<>"",$H32,$E32)*INDEX(Summary!$C$6:$C$8,MATCH($P32,Summary!$B$6:$B$8,0)),0) -> 400 | W32: Estimate
A33: E24 | B33: Head bolts (OEM TTY) — alternative to studs | C33: 1 | D33: 55 | E33: 100 | F33: N | G33: N | I33: =IF(AND($K33="Y",$F33<>"Y",OR($T33="",$T33=Summary!$C$11)),$C33*IF($H33<>"",$H33,($D33+$E33)/2)*INDEX(Summary!$C$6:$C$8,MATCH($P33,Summary!$B$6:$B$8,0)),0) -> 0 | J33: Option | K33: N | L33: Engine prep | M33: Head | N33: Pick E23 or E24. | O33: set | P33: CAD | Q33: Buy | R33: ECS | S33: 3 Turbo | U33: =IF(AND($K33="Y",$F33<>"Y",OR($T33="",$T33=Summary!$C$11)),$C33*IF($H33<>"",$H33,$D33)*INDEX(Summary!$C$6:$C$8,MATCH($P33,Summary!$B$6:$B$8,0)),0) -> 0 | V33: =IF(AND($K33="Y",$F33<>"Y",OR($T33="",$T33=Summary!$C$11)),$C33*IF($H33<>"",$H33,$E33)*INDEX(Summary!$C$6:$C$8,MATCH($P33,Summary!$B$6:$B$8,0)),0) -> 0 | W33: Estimate
A34: E25 | B34: Degreaser, brushes, engine paint | C34: 1 | D34: 30 | E34: 60 | F34: N | G34: N | I34: =IF(AND($K34="Y",$F34<>"Y",OR($T34="",$T34=Summary!$C$11)),$C34*IF($H34<>"",$H34,($D34+$E34)/2)*INDEX(Summary!$C$6:$C$8,MATCH($P34,Summary!$B$6:$B$8,0)),0) -> 45 | J34: Need | K34: Y | L34: Engine prep | M34: Clean | O34: lot | P34: CAD | Q34: Buy | R34: Canadian Tire | S34: 2 NA swap | U34: =IF(AND($K34="Y",$F34<>"Y",OR($T34="",$T34=Summary!$C$11)),$C34*IF($H34<>"",$H34,$D34)*INDEX(Summary!$C$6:$C$8,MATCH($P34,Summary!$B$6:$B$8,0)),0) -> 30 | V34: =IF(AND($K34="Y",$F34<>"Y",OR($T34="",$T34=Summary!$C$11)),$C34*IF($H34<>"",$H34,$E34)*INDEX(Summary!$C$6:$C$8,MATCH($P34,Summary!$B$6:$B$8,0)),0) -> 60 | W34: Estimate
A35: G01 | B35: Mazda RX-8 6-speed manual (Aisin AZ6), used | C35: 1 | D35: 605 | E35: 1415 | F35: N | G35: N | I35: =IF(AND($K35="Y",$F35<>"Y",OR($T35="",$T35=Summary!$C$11)),$C35*IF($H35<>"",$H35,($D35+$E35)/2)*INDEX(Summary!$C$6:$C$8,MATCH($P35,Summary!$B$6:$B$8,0)),0) -> 1010 | J35: Need | K35: Y | L35: Gearbox: RX-8 | M35: Gearbox | N35: S1 2004–08. Comes with its slave, release bearing, shifter, flange. Ask for the shifter and bolts. | O35: ea | P35: CAD | Q35: Buy | R35: eBay / JDM importer | S35: 2 NA swap | T35: RX-8 | U35: =IF(AND($K35="Y",$F35<>"Y",OR($T35="",$T35=Summary!$C$11)),$C35*IF($H35<>"",$H35,$D35)*INDEX(Summary!$C$6:$C$8,MATCH($P35,Summary!$B$6:$B$8,0)),0) -> 605 | V35: =IF(AND($K35="Y",$F35<>"Y",OR($T35="",$T35=Summary!$C$11)),$C35*IF($H35<>"",$H35,$E35)*INDEX(Summary!$C$6:$C$8,MATCH($P35,Summary!$B$6:$B$8,0)),0) -> 1415 | W35: Verified | X35: https://www.ebay.com/b/Complete-Manual-Transmissions-for-Mazda-RX-8/171117/bn_1435951
A36: G02 | B36: Gearbox freight | C36: 1 | D36: 215 | E36: 495 | F36: N | G36: N | I36: =IF(AND($K36="Y",$F36<>"Y",OR($T36="",$T36=Summary!$C$11)),$C36*IF($H36<>"",$H36,($D36+$E36)/2)*INDEX(Summary!$C$6:$C$8,MATCH($P36,Summary!$B$6:$B$8,0)),0) -> 355 | J36: Need | K36: Y | L36: Gearbox: RX-8 | M36: Gearbox | O36: ea | P36: CAD | Q36: Buy | R36: — | S36: 2 NA swap | T36: RX-8 | U36: =IF(AND($K36="Y",$F36<>"Y",OR($T36="",$T36=Summary!$C$11)),$C36*IF($H36<>"",$H36,$D36)*INDEX(Summary!$C$6:$C$8,MATCH($P36,Summary!$B$6:$B$8,0)),0) -> 215 | V36: =IF(AND($K36="Y",$F36<>"Y",OR($T36="",$T36=Summary!$C$11)),$C36*IF($H36<>"",$H36,$E36)*INDEX(Summary!$C$6:$C$8,MATCH($P36,Summary!$B$6:$B$8,0)),0) -> 495 | W36: Verified
A37: G03 | B37: Gear oil 75W-90 GL-4 (2 L) | C37: 1 | D37: 35 | E37: 70 | F37: N | G37: N | I37: =IF(AND($K37="Y",$F37<>"Y",OR($T37="",$T37=Summary!$C$11)),$C37*IF($H37<>"",$H37,($D37+$E37)/2)*INDEX(Summary!$C$6:$C$8,MATCH($P37,Summary!$B$6:$B$8,0)),0) -> 52.5 | J37: Need | K37: Y | L37: Gearbox: RX-8 | M37: Gearbox | O37: ea | P37: CAD | Q37: Buy | R37: Any | S37: 2 NA swap | T37: RX-8 | U37: =IF(AND($K37="Y",$F37<>"Y",OR($T37="",$T37=Summary!$C$11)),$C37*IF($H37<>"",$H37,$D37)*INDEX(Summary!$C$6:$C$8,MATCH($P37,Summary!$B$6:$B$8,0)),0) -> 35 | V37: =IF(AND($K37="Y",$F37<>"Y",OR($T37="",$T37=Summary!$C$11)),$C37*IF($H37<>"",$H37,$E37)*INDEX(Summary!$C$6:$C$8,MATCH($P37,Summary!$B$6:$B$8,0)),0) -> 70 | W37: Estimate
A38: G04 | B38: Shift knob + boot | C38: 1 | D38: 0 | E38: 55 | F38: N | G38: N | I38: =IF(AND($K38="Y",$F38<>"Y",OR($T38="",$T38=Summary!$C$11)),$C38*IF($H38<>"",$H38,($D38+$E38)/2)*INDEX(Summary!$C$6:$C$8,MATCH($P38,Summary!$B$6:$B$8,0)),0) -> 27.5 | J38: To decide | K38: Y | L38: Gearbox: RX-8 | M38: Gearbox | N38: Stock RX-8 knob is M10×1.25 — ZN6 knob fits? check. | O38: ea | P38: CAD | Q38: Buy | R38: — | S38: 2 NA swap | T38: RX-8 | U38: =IF(AND($K38="Y",$F38<>"Y",OR($T38="",$T38=Summary!$C$11)),$C38*IF($H38<>"",$H38,$D38)*INDEX(Summary!$C$6:$C$8,MATCH($P38,Summary!$B$6:$B$8,0)),0) -> 0 | V38: =IF(AND($K38="Y",$F38<>"Y",OR($T38="",$T38=Summary!$C$11)),$C38*IF($H38<>"",$H38,$E38)*INDEX(Summary!$C$6:$C$8,MATCH($P38,Summary!$B$6:$B$8,0)),0) -> 55 | W38: Estimate
A39: G05 | B39: MAKE: 6061-T6 plate blank, ~16 × 16 in × 1 in | C39: 1 | D39: 215 | E39: 425 | F39: N | G39: Y | I39: =IF(AND($K39="Y",$F39<>"Y",OR($T39="",$T39=Summary!$C$11)),$C39*IF($H39<>"",$H39,($D39+$E39)/2)*INDEX(Summary!$C$6:$C$8,MATCH($P39,Summary!$B$6:$B$8,0)),0) -> 320 | J39: Need | K39: Y | L39: Gearbox: RX-8 | M39: Adapter plate | N39: Thickness T comes from the stack-up (§13). 1 in blank, faced down. Metal Supermarkets Ottawa or online. | O39: ea | P39: CAD | Q39: Make | R39: Metal Supermarkets / OnlineMetals | S39: 2 NA swap | T39: RX-8 | U39: =IF(AND($K39="Y",$F39<>"Y",OR($T39="",$T39=Summary!$C$11)),$C39*IF($H39<>"",$H39,$D39)*INDEX(Summary!$C$6:$C$8,MATCH($P39,Summary!$B$6:$B$8,0)),0) -> 215 | V39: =IF(AND($K39="Y",$F39<>"Y",OR($T39="",$T39=Summary!$C$11)),$C39*IF($H39<>"",$H39,$E39)*INDEX(Summary!$C$6:$C$8,MATCH($P39,Summary!$B$6:$B$8,0)),0) -> 425 | W39: Estimate | X39: https://www.onlinemetals.com/en/buy/aluminum-sheet-plate-6061
A40: G06 | B40: Dowel pins, hardened — VW block side (2) | C40: 2 | D40: 6 | E40: 14 | F40: N | G40: N | I40: =IF(AND($K40="Y",$F40<>"Y",OR($T40="",$T40=Summary!$C$11)),$C40*IF($H40<>"",$H40,($D40+$E40)/2)*INDEX(Summary!$C$6:$C$8,MATCH($P40,Summary!$B$6:$B$8,0)),0) -> 20 | J40: Need | K40: Y | L40: Gearbox: RX-8 | M40: Adapter plate | N40: Match the 07K/02J dowel diameter (measure). | O40: ea | P40: CAD | Q40: Buy | R40: McMaster / Fastenal | S40: 2 NA swap | T40: RX-8 | U40: =IF(AND($K40="Y",$F40<>"Y",OR($T40="",$T40=Summary!$C$11)),$C40*IF($H40<>"",$H40,$D40)*INDEX(Summary!$C$6:$C$8,MATCH($P40,Summary!$B$6:$B$8,0)),0) -> 12 | V40: =IF(AND($K40="Y",$F40<>"Y",OR($T40="",$T40=Summary!$C$11)),$C40*IF($H40<>"",$H40,$E40)*INDEX(Summary!$C$6:$C$8,MATCH($P40,Summary!$B$6:$B$8,0)),0) -> 28 | W40: Estimate
A41: G07 | B41: Dowel pins, hardened — RX-8 bell side (2) | C41: 2 | D41: 6 | E41: 14 | F41: N | G41: N | I41: =IF(AND($K41="Y",$F41<>"Y",OR($T41="",$T41=Summary!$C$11)),$C41*IF($H41<>"",$H41,($D41+$E41)/2)*INDEX(Summary!$C$6:$C$8,MATCH($P41,Summary!$B$6:$B$8,0)),0) -> 20 | J41: Need | K41: Y | L41: Gearbox: RX-8 | M41: Adapter plate | N41: Match the RX-8 bellhousing dowel diameter (measure). | O41: ea | P41: CAD | Q41: Buy | R41: McMaster / Fastenal | S41: 2 NA swap | T41: RX-8 | U41: =IF(AND($K41="Y",$F41<>"Y",OR($T41="",$T41=Summary!$C$11)),$C41*IF($H41<>"",$H41,$D41)*INDEX(Summary!$C$6:$C$8,MATCH($P41,Summary!$B$6:$B$8,0)),0) -> 12 | V41: =IF(AND($K41="Y",$F41<>"Y",OR($T41="",$T41=Summary!$C$11)),$C41*IF($H41<>"",$H41,$E41)*INDEX(Summary!$C$6:$C$8,MATCH($P41,Summary!$B$6:$B$8,0)),0) -> 28 | W41: Estimate
...

Sheet CNC
A1: 07K ZN6 — CNC mill BOM (HTMCNC-style, 450 x 750 x 110 mm work area)
A2: Same rules as the BOM tab. Blue column H = your real price (CAD). Lines with NO price are undecided: fill D/E with an estimate or H with the real price once you pick a listing. Decided so far (Oct 4, 2026): motor/driver/supply kit (Amazon), extrusion (Amazon). Have: Arduino UNO, filament. Candidate AliExpress listings are in the Link column; prices for those are NOT entered on purpose.
A4: ID | B4: Part | C4: Qty | D4: Est. low | E4: Est. high | F4: Have? | G4: Make? | H4: MY cost | I4: Working (CAD) | J4: Status | K4: Incl. | L4: System | M4: Sub-assembly | N4: Spec / notes | O4: Unit | P4: Cur | Q4: Source | R4: Vendor / ref | S4: Phase | T4: Route | U4: Ext low (CAD) | V4: Ext high (CAD) | W4: Basis | X4: Link
A5: C01 | B5: 2040 T-slot extrusion, 1000 mm, black — VEVOR 5-pack | C5: 1 | F5: N | G5: N | H5: 57.99 | I5: =IF(AND($K5="Y",$F5<>"Y",OR($T5="",$T5=Summary!$C$11)),$C5*IF($H5<>"",$H5,($D5+$E5)/2)*INDEX(Summary!$C$6:$C$8,MATCH($P5,Summary!$B$6:$B$8,0)),0) -> 57.99 | J5: Need | K5: Y | L5: CNC: Frame | M5: Extrusion | N5: Cut plan: two bars → 700 + 200 + 100; three bars stay 600. Cut 2–3 mm long, file square. Decided Oct 4: Amazon. | O5: pack | P5: CAD | Q5: Buy | R5: Amazon B0F47W71ZD | S5: CNC build | U5: =IF(AND($K5="Y",$F5<>"Y",OR($T5="",$T5=Summary!$C$11)),$C5*IF($H5<>"",$H5,$D5)*INDEX(Summary!$C$6:$C$8,MATCH($P5,Summary!$B$6:$B$8,0)),0) -> 57.99 | V5: =IF(AND($K5="Y",$F5<>"Y",OR($T5="",$T5=Summary!$C$11)),$C5*IF($H5<>"",$H5,$E5)*INDEX(Summary!$C$6:$C$8,MATCH($P5,Summary!$B$6:$B$8,0)),0) -> 57.99 | W5: Verified | X5: https://www.amazon.ca/dp/B0F47W71ZD
A6: C02 | B6: 2080 T-slot extrusion, 1000 mm, silver — 2-pack (Y rails) | C6: 1 | F6: N | G6: N | H6: 106.99 | I6: =IF(AND($K6="Y",$F6<>"Y",OR($T6="",$T6=Summary!$C$11)),$C6*IF($H6<>"",$H6,($D6+$E6)/2)*INDEX(Summary!$C$6:$C$8,MATCH($P6,Summary!$B$6:$B$8,0)),0) -> 106.99 | J6: Need | K6: Y | L6: CNC: Frame | M6: Extrusion | N6: Check the variant selector is on 1000 mm silver before buying. Decided Oct 4: Amazon. Alt: Spool3D 2080 V-slot 1000 mm. | O6: pack | P6: CAD | Q6: Buy | R6: Amazon B09MWBZRGH | S6: CNC build | U6: =IF(AND($K6="Y",$F6<>"Y",OR($T6="",$T6=Summary!$C$11)),$C6*IF($H6<>"",$H6,$D6)*INDEX(Summary!$C$6:$C$8,MATCH($P6,Summary!$B$6:$B$8,0)),0) -> 106.99 | V6: =IF(AND($K6="Y",$F6<>"Y",OR($T6="",$T6=Summary!$C$11)),$C6*IF($H6<>"",$H6,$E6)*INDEX(Summary!$C$6:$C$8,MATCH($P6,Summary!$B$6:$B$8,0)),0) -> 106.99 | W6: Verified | X6: https://www.amazon.ca/dp/B09MWBZRGH
A7: C03 | B7: Corner bracket 28x20x28 (2028), with T-nuts + M5 bolts | C7: 18 | F7: N | G7: N | I7: =IF(AND($K7="Y",$F7<>"Y",OR($T7="",$T7=Summary!$C$11)),$C7*IF($H7<>"",$H7,($D7+$E7)/2)*INDEX(Summary!$C$6:$C$8,MATCH($P7,Summary!$B$6:$B$8,0)),0) -> 0 | J7: Need | K7: Y | L7: CNC: Frame | M7: Hardware | N7: Author's BOM: 18. Sold in 10-packs → buy 2 packs. | O7: ea | P7: CAD | Q7: Buy | R7: AliExpress 1005007660268625 | S7: CNC build | U7: =IF(AND($K7="Y",$F7<>"Y",OR($T7="",$T7=Summary!$C$11)),$C7*IF($H7<>"",$H7,$D7)*INDEX(Summary!$C$6:$C$8,MATCH($P7,Summary!$B$6:$B$8,0)),0) -> 0 | V7: =IF(AND($K7="Y",$F7<>"Y",OR($T7="",$T7=Summary!$C$11)),$C7*IF($H7<>"",$H7,$E7)*INDEX(Summary!$C$6:$C$8,MATCH($P7,Summary!$B$6:$B$8,0)),0) -> 0 | W7: Notes | X7: https://www.aliexpress.com/item/1005007660268625.html
A8: C04 | B8: Corner bracket 20x20x20, with T-nuts + M5 bolts | C8: 8 | F8: N | G8: N | I8: =IF(AND($K8="Y",$F8<>"Y",OR($T8="",$T8=Summary!$C$11)),$C8*IF($H8<>"",$H8,($D8+$E8)/2)*INDEX(Summary!$C$6:$C$8,MATCH($P8,Summary!$B$6:$B$8,0)),0) -> 0 | J8: Need | K8: Y | L8: CNC: Frame | M8: Hardware | N8: Author's BOM: 8. | O8: ea | P8: CAD | Q8: Buy | R8: AliExpress 1005002491882309 | S8: CNC build | U8: =IF(AND($K8="Y",$F8<>"Y",OR($T8="",$T8=Summary!$C$11)),$C8*IF($H8<>"",$H8,$D8)*INDEX(Summary!$C$6:$C$8,MATCH($P8,Summary!$B$6:$B$8,0)),0) -> 0 | V8: =IF(AND($K8="Y",$F8<>"Y",OR($T8="",$T8=Summary!$C$11)),$C8*IF($H8<>"",$H8,$E8)*INDEX(Summary!$C$6:$C$8,MATCH($P8,Summary!$B$6:$B$8,0)),0) -> 0 | W8: Notes | X8: https://www.aliexpress.com/item/1005002491882309.html
A9: C05 | B9: M5 sliding T-nut | C9: 100 | F9: N | G9: N | I9: =IF(AND($K9="Y",$F9<>"Y",OR($T9="",$T9=Summary!$C$11)),$C9*IF($H9<>"",$H9,($D9+$E9)/2)*INDEX(Summary!$C$6:$C$8,MATCH($P9,Summary!$B$6:$B$8,0)),0) -> 0 | J9: Need | K9: Y | L9: CNC: Frame | M9: Hardware | N9: 20-series, 6 mm slot. | O9: ea | P9: CAD | Q9: Buy | R9: AliExpress 1005007883028035 | S9: CNC build | U9: =IF(AND($K9="Y",$F9<>"Y",OR($T9="",$T9=Summary!$C$11)),$C9*IF($H9<>"",$H9,$D9)*INDEX(Summary!$C$6:$C$8,MATCH($P9,Summary!$B$6:$B$8,0)),0) -> 0 | V9: =IF(AND($K9="Y",$F9<>"Y",OR($T9="",$T9=Summary!$C$11)),$C9*IF($H9<>"",$H9,$E9)*INDEX(Summary!$C$6:$C$8,MATCH($P9,Summary!$B$6:$B$8,0)),0) -> 0 | W9: Notes | X9: https://www.aliexpress.com/item/1005007883028035.html
A10: C06 | B10: M5 hammer-head T-nut | C10: 100 | F10: N | G10: N | I10: =IF(AND($K10="Y",$F10<>"Y",OR($T10="",$T10=Summary!$C$11)),$C10*IF($H10<>"",$H10,($D10+$E10)/2)*INDEX(Summary!$C$6:$C$8,MATCH($P10,Summary!$B$6:$B$8,0)),0) -> 0 | J10: Need | K10: Y | L10: CNC: Frame | M10: Hardware | N10: Drop-in type for adding parts after assembly. | O10: ea | P10: CAD | Q10: Buy | R10: AliExpress 32814359094 | S10: CNC build | U10: =IF(AND($K10="Y",$F10<>"Y",OR($T10="",$T10=Summary!$C$11)),$C10*IF($H10<>"",$H10,$D10)*INDEX(Summary!$C$6:$C$8,MATCH($P10,Summary!$B$6:$B$8,0)),0) -> 0 | V10: =IF(AND($K10="Y",$F10<>"Y",OR($T10="",$T10=Summary!$C$11)),$C10*IF($H10<>"",$H10,$E10)*INDEX(Summary!$C$6:$C$8,MATCH($P10,Summary!$B$6:$B$8,0)),0) -> 0 | W10: Notes | X10: https://www.aliexpress.com/item/32814359094.html
A11: C07 | B11: M4 sliding T-nut | C11: 50 | F11: N | G11: N | I11: =IF(AND($K11="Y",$F11<>"Y",OR($T11="",$T11=Summary!$C$11)),$C11*IF($H11<>"",$H11,($D11+$E11)/2)*INDEX(Summary!$C$6:$C$8,MATCH($P11,Summary!$B$6:$B$8,0)),0) -> 0 | J11: Need | K11: Y | L11: CNC: Frame | M11: Hardware | O11: ea | P11: CAD | Q11: Buy | R11: AliExpress 1005007883028035 | S11: CNC build | U11: =IF(AND($K11="Y",$F11<>"Y",OR($T11="",$T11=Summary!$C$11)),$C11*IF($H11<>"",$H11,$D11)*INDEX(Summary!$C$6:$C$8,MATCH($P11,Summary!$B$6:$B$8,0)),0) -> 0 | V11: =IF(AND($K11="Y",$F11<>"Y",OR($T11="",$T11=Summary!$C$11)),$C11*IF($H11<>"",$H11,$E11)*INDEX(Summary!$C$6:$C$8,MATCH($P11,Summary!$B$6:$B$8,0)),0) -> 0 | W11: Notes | X11: https://www.aliexpress.com/item/1005007883028035.html
A12: C08 | B12: M4 hammer-head T-nut | C12: 50 | F12: N | G12: N | I12: =IF(AND($K12="Y",$F12<>"Y",OR($T12="",$T12=Summary!$C$11)),$C12*IF($H12<>"",$H12,($D12+$E12)/2)*INDEX(Summary!$C$6:$C$8,MATCH($P12,Summary!$B$6:$B$8,0)),0) -> 0 | J12: Need | K12: Y | L12: CNC: Frame | M12: Hardware | O12: ea | P12: CAD | Q12: Buy | R12: AliExpress 32814359094 | S12: CNC build | U12: =IF(AND($K12="Y",$F12<>"Y",OR($T12="",$T12=Summary!$C$11)),$C12*IF($H12<>"",$H12,$D12)*INDEX(Summary!$C$6:$C$8,MATCH($P12,Summary!$B$6:$B$8,0)),0) -> 0 | V12: =IF(AND($K12="Y",$F12<>"Y",OR($T12="",$T12=Summary!$C$11)),$C12*IF($H12<>"",$H12,$E12)*INDEX(Summary!$C$6:$C$8,MATCH($P12,Summary!$B$6:$B$8,0)),0) -> 0 | W12: Notes | X12: https://www.aliexpress.com/item/32814359094.html
A13: C09 | B13: Socket-head bolt kit (author's list) | C13: 1 | F13: N | G13: N | I13: =IF(AND($K13="Y",$F13<>"Y",OR($T13="",$T13=Summary!$C$11)),$C13*IF($H13<>"",$H13,($D13+$E13)/2)*INDEX(Summary!$C$6:$C$8,MATCH($P13,Summary!$B$6:$B$8,0)),0) -> 0 | J13: Need | K13: Y | L13: CNC: Frame | M13: Hardware | N13: M3x12 ×10, M3x16 ×5, M3x30 ×5, M4x10 ×5, M4x12 ×5, M4x14 ×60, M4x25 ×10, M5x12 ×50, M5x16 ×40, M5x20 ×40, M5x30 ×40, M5x50 ×25, M5x60 ×35, M5x70 ×5. Cheapest as an assorted M4/M5 kit. | O13: kit | P13: CAD | Q13: Buy | R13: Amazon / AliExpress | S13: CNC build | U13: =IF(AND($K13="Y",$F13<>"Y",OR($T13="",$T13=Summary!$C$11)),$C13*IF($H13<>"",$H13,$D13)*INDEX(Summary!$C$6:$C$8,MATCH($P13,Summary!$B$6:$B$8,0)),0) -> 0 | V13: =IF(AND($K13="Y",$F13<>"Y",OR($T13="",$T13=Summary!$C$11)),$C13*IF($H13<>"",$H13,$E13)*INDEX(Summary!$C$6:$C$8,MATCH($P13,Summary!$B$6:$B$8,0)),0) -> 0 | W13: Notes
A14: C10 | B14: HGR15 linear rail 1000 mm + 2 HGH15CA blocks (Y) | C14: 2 | F14: N | G14: N | I14: =IF(AND($K14="Y",$F14<>"Y",OR($T14="",$T14=Summary!$C$11)),$C14*IF($H14<>"",$H14,($D14+$E14)/2)*INDEX(Summary!$C$6:$C$8,MATCH($P14,Summary!$B$6:$B$8,0)),0) -> 0 | J14: Need | K14: Y | L14: CNC: Motion | M14: Linear rails | N14: Y scaled to 750 mm travel: 600 + 400. Buy as a 2-rail + 4-block set. | O14: ea | P14: CAD | Q14: Buy | R14: AliExpress 1005004825209262 | S14: CNC build | U14: =IF(AND($K14="Y",$F14<>"Y",OR($T14="",$T14=Summary!$C$11)),$C14*IF($H14<>"",$H14,$D14)*INDEX(Summary!$C$6:$C$8,MATCH($P14,Summary!$B$6:$B$8,0)),0) -> 0 | V14: =IF(AND($K14="Y",$F14<>"Y",OR($T14="",$T14=Summary!$C$11)),$C14*IF($H14<>"",$H14,$E14)*INDEX(Summary!$C$6:$C$8,MATCH($P14,Summary!$B$6:$B$8,0)),0) -> 0 | W14: Notes | X14: https://www.aliexpress.com/item/1005004825209262.html
A15: C11 | B15: HGR15 linear rail 600 mm + 2 HGH15CA blocks (X) | C15: 2 | F15: N | G15: N | I15: =IF(AND($K15="Y",$F15<>"Y",OR($T15="",$T15=Summary!$C$11)),$C15*IF($H15<>"",$H15,($D15+$E15)/2)*INDEX(Summary!$C$6:$C$8,MATCH($P15,Summary!$B$6:$B$8,0)),0) -> 0 | J15: Need | K15: Y | L15: CNC: Motion | M15: Linear rails | N15: Same listing, 600 mm option. | O15: ea | P15: CAD | Q15: Buy | R15: AliExpress 1005004825209262 | S15: CNC build | U15: =IF(AND($K15="Y",$F15<>"Y",OR($T15="",$T15=Summary!$C$11)),$C15*IF($H15<>"",$H15,$D15)*INDEX(Summary!$C$6:$C$8,MATCH($P15,Summary!$B$6:$B$8,0)),0) -> 0 | V15: =IF(AND($K15="Y",$F15<>"Y",OR($T15="",$T15=Summary!$C$11)),$C15*IF($H15<>"",$H15,$E15)*INDEX(Summary!$C$6:$C$8,MATCH($P15,Summary!$B$6:$B$8,0)),0) -> 0 | W15: Notes | X15: https://www.aliexpress.com/item/1005004825209262.html
A16: C12 | B16: HGR15 linear rail 300 mm + 2 HGH15CA blocks (Z) | C16: 2 | F16: N | G16: N | I16: =IF(AND($K16="Y",$F16<>"Y",OR($T16="",$T16=Summary!$C$11)),$C16*IF($H16<>"",$H16,($D16+$E16)/2)*INDEX(Summary!$C$6:$C$8,MATCH($P16,Summary!$B$6:$B$8,0)),0) -> 0 | J16: Need | K16: Y | L16: CNC: Motion | M16: Linear rails | N16: Same listing, 300 mm option; fixed-length alt 1005012673253692. | O16: ea | P16: CAD | Q16: Buy | R16: AliExpress 1005004825209262 | S16: CNC build | U16: =IF(AND($K16="Y",$F16<>"Y",OR($T16="",$T16=Summary!$C$11)),$C16*IF($H16<>"",$H16,$D16)*INDEX(Summary!$C$6:$C$8,MATCH($P16,Summary!$B$6:$B$8,0)),0) -> 0 | V16: =IF(AND($K16="Y",$F16<>"Y",OR($T16="",$T16=Summary!$C$11)),$C16*IF($H16<>"",$H16,$E16)*INDEX(Summary!$C$6:$C$8,MATCH($P16,Summary!$B$6:$B$8,0)),0) -> 0 | W16: Notes | X16: https://www.aliexpress.com/item/1005004825209262.html
A17: C13 | B17: SFU1605 ballscrew 900 mm, flange nut, ends machined (Y) | C17: 2 | F17: N | G17: N | I17: =IF(AND($K17="Y",$F17<>"Y",OR($T17="",$T17=Summary!$C$11)),$C17*IF($H17<>"",$H17,($D17+$E17)/2)*INDEX(Summary!$C$6:$C$8,MATCH($P17,Summary!$B$6:$B$8,0)),0) -> 0 | J17: Need | K17: Y | L17: CNC: Motion | M17: Ballscrews | N17: C7 rolled. Y = 500 + 400. Check critical speed for 900 mm (author's note). | O17: ea | P17: CAD | Q17: Buy | R17: AliExpress 1005007791178337 | S17: CNC build | U17: =IF(AND($K17="Y",$F17<>"Y",OR($T17="",$T17=Summary!$C$11)),$C17*IF($H17<>"",$H17,$D17)*INDEX(Summary!$C$6:$C$8,MATCH($P17,Summary!$B$6:$B$8,0)),0) -> 0 | V17: =IF(AND($K17="Y",$F17<>"Y",OR($T17="",$T17=Summary!$C$11)),$C17*IF($H17<>"",$H17,$E17)*INDEX(Summary!$C$6:$C$8,MATCH($P17,Summary!$B$6:$B$8,0)),0) -> 0 | W17: Notes | X17: https://www.aliexpress.com/item/1005007791178337.html
A18: C14 | B18: SFU1605 ballscrew 600 mm, flange nut, ends machined (X) | C18: 1 | F18: N | G18: N | I18: =IF(AND($K18="Y",$F18<>"Y",OR($T18="",$T18=Summary!$C$11)),$C18*IF($H18<>"",$H18,($D18+$E18)/2)*INDEX(Summary!$C$6:$C$8,MATCH($P18,Summary!$B$6:$B$8,0)),0) -> 0 | J18: Need | K18: Y | L18: CNC: Motion | M18: Ballscrews | O18: ea | P18: CAD | Q18: Buy | R18: AliExpress 1005007791178337 | S18: CNC build | U18: =IF(AND($K18="Y",$F18<>"Y",OR($T18="",$T18=Summary!$C$11)),$C18*IF($H18<>"",$H18,$D18)*INDEX(Summary!$C$6:$C$8,MATCH($P18,Summary!$B$6:$B$8,0)),0) -> 0 | V18: =IF(AND($K18="Y",$F18<>"Y",OR($T18="",$T18=Summary!$C$11)),$C18*IF($H18<>"",$H18,$E18)*INDEX(Summary!$C$6:$C$8,MATCH($P18,Summary!$B$6:$B$8,0)),0) -> 0 | W18: Notes | X18: https://www.aliexpress.com/item/1005007791178337.html
A19: C15 | B19: SFU1605 ballscrew 300 mm, flange nut, ends machined (Z) | C19: 1 | F19: N | G19: N | I19: =IF(AND($K19="Y",$F19<>"Y",OR($T19="",$T19=Summary!$C$11)),$C19*IF($H19<>"",$H19,($D19+$E19)/2)*INDEX(Summary!$C$6:$C$8,MATCH($P19,Summary!$B$6:$B$8,0)),0) -> 0 | J19: Need | K19: Y | L19: CNC: Motion | M19: Ballscrews | N19: Fixed-length listing with 105 orders. | O19: ea | P19: CAD | Q19: Buy | R19: AliExpress 32995243964 | S19: CNC build | U19: =IF(AND($K19="Y",$F19<>"Y",OR($T19="",$T19=Summary!$C$11)),$C19*IF($H19<>"",$H19,$D19)*INDEX(Summary!$C$6:$C$8,MATCH($P19,Summary!$B$6:$B$8,0)),0) -> 0 | V19: =IF(AND($K19="Y",$F19<>"Y",OR($T19="",$T19=Summary!$C$11)),$C19*IF($H19<>"",$H19,$E19)*INDEX(Summary!$C$6:$C$8,MATCH($P19,Summary!$B$6:$B$8,0)),0) -> 0 | W19: Notes | X19: https://www.aliexpress.com/item/32995243964.html
A20: C16 | B20: 7001 angular contact bearing, P5, DB pair (12x28x8) | C20: 4 | F20: N | G20: N | I20: =IF(AND($K20="Y",$F20<>"Y",OR($T20="",$T20=Summary!$C$11)),$C20*IF($H20<>"",$H20,($D20+$E20)/2)*INDEX(Summary!$C$6:$C$8,MATCH($P20,Summary!$B$6:$B$8,0)),0) -> 0 | J20: Need | K20: Y | L20: CNC: Motion | M20: Bearing blocks | N20: One pair per printed ballscrew bearing block. | O20: pair | P20: CAD | Q20: Buy | R20: AliExpress 32794645480 | S20: CNC build | U20: =IF(AND($K20="Y",$F20<>"Y",OR($T20="",$T20=Summary!$C$11)),$C20*IF($H20<>"",$H20,$D20)*INDEX(Summary!$C$6:$C$8,MATCH($P20,Summary!$B$6:$B$8,0)),0) -> 0 | V20: =IF(AND($K20="Y",$F20<>"Y",OR($T20="",$T20=Summary!$C$11)),$C20*IF($H20<>"",$H20,$E20)*INDEX(Summary!$C$6:$C$8,MATCH($P20,Summary!$B$6:$B$8,0)),0) -> 0 | W20: Notes | X20: https://www.aliexpress.com/item/32794645480.html
A21: C17 | B21: 6000-2RS bearing (10x26x8) | C21: 4 | F21: N | G21: N | I21: =IF(AND($K21="Y",$F21<>"Y",OR($T21="",$T21=Summary!$C$11)),$C21*IF($H21<>"",$H21,($D21+$E21)/2)*INDEX(Summary!$C$6:$C$8,MATCH($P21,Summary!$B$6:$B$8,0)),0) -> 0 | J21: Need | K21: Y | L21: CNC: Motion | M21: Bearing blocks | N21: Floating-end bearings. | O21: ea | P21: CAD | Q21: Buy | R21: AliExpress 1005006093979302 | S21: CNC build | U21: =IF(AND($K21="Y",$F21<>"Y",OR($T21="",$T21=Summary!$C$11)),$C21*IF($H21<>"",$H21,$D21)*INDEX(Summary!$C$6:$C$8,MATCH($P21,Summary!$B$6:$B$8,0)),0) -> 0 | V21: =IF(AND($K21="Y",$F21<>"Y",OR($T21="",$T21=Summary!$C$11)),$C21*IF($H21<>"",$H21,$E21)*INDEX(Summary!$C$6:$C$8,MATCH($P21,Summary!$B$6:$B$8,0)),0) -> 0 | W21: Notes | X21: https://www.aliexpress.com/item/1005006093979302.html
A22: C18 | B22: M12x1 locknut (ballscrew end) | C22: 4 | F22: N | G22: N | I22: =IF(AND($K22="Y",$F22<>"Y",OR($T22="",$T22=Summary!$C$11)),$C22*IF($H22<>"",$H22,($D22+$E22)/2)*INDEX(Summary!$C$6:$C$8,MATCH($P22,Summary!$B$6:$B$8,0)),0) -> 0 | J22: Need | K22: Y | L22: CNC: Motion | M22: Bearing blocks | N22: Also included in BK12 support kits. | O22: ea | P22: CAD | Q22: Buy | R22: AliExpress | S22: CNC build | U22: =IF(AND($K22="Y",$F22<>"Y",OR($T22="",$T22=Summary!$C$11)),$C22*IF($H22<>"",$H22,$D22)*INDEX(Summary!$C$6:$C$8,MATCH($P22,Summary!$B$6:$B$8,0)),0) -> 0 | V22: =IF(AND($K22="Y",$F22<>"Y",OR($T22="",$T22=Summary!$C$11)),$C22*IF($H22<>"",$H22,$E22)*INDEX(Summary!$C$6:$C$8,MATCH($P22,Summary!$B$6:$B$8,0)),0) -> 0 | W22: Notes
A23: C19 | B23: Shaft coupler 8 mm to 10 mm, jaw type D19 L25 | C23: 4 | F23: N | G23: N | I23: =IF(AND($K23="Y",$F23<>"Y",OR($T23="",$T23=Summary!$C$11)),$C23*IF($H23<>"",$H23,($D23+$E23)/2)*INDEX(Summary!$C$6:$C$8,MATCH($P23,Summary!$B$6:$B$8,0)),0) -> 0 | J23: Need | K23: Y | L23: CNC: Motion | M23: Drive | N23: Motor shaft 8 mm → screw end 10 mm. | O23: ea | P23: CAD | Q23: Buy | R23: AliExpress 1005007121900242 | S23: CNC build | U23: =IF(AND($K23="Y",$F23<>"Y",OR($T23="",$T23=Summary!$C$11)),$C23*IF($H23<>"",$H23,$D23)*INDEX(Summary!$C$6:$C$8,MATCH($P23,Summary!$B$6:$B$8,0)),0) -> 0 | V23: =IF(AND($K23="Y",$F23<>"Y",OR($T23="",$T23=Summary!$C$11)),$C23*IF($H23<>"",$H23,$E23)*INDEX(Summary!$C$6:$C$8,MATCH($P23,Summary!$B$6:$B$8,0)),0) -> 0 | W23: Notes | X23: https://www.aliexpress.com/item/1005007121900242.html
A24: C20 | B24: Motor / driver / supply kit: 4× NEMA 23 2.2 Nm, 4× TB6600, 36 V 350 W, Mach3 USB card | C24: 1 | F24: N | G24: N | H24: 185 | I24: =IF(AND($K24="Y",$F24<>"Y",OR($T24="",$T24=Summary!$C$11)),$C24*IF($H24<>"",$H24,($D24+$E24)/2)*INDEX(Summary!$C$6:$C$8,MATCH($P24,Summary!$B$6:$B$8,0)),0) -> 185 | J24: Need | K24: Y | L24: CNC: Electronics | M24: Motion control | N24: Decided Oct 4. Set TB6600 to ~2.5 A, 1/8–1/16 microstep. Treat the Mach3 USB card as a spare; GRBL runs on the UNO. Check motor body length vs the printed Y and Z mounts. | O24: kit | P24: CAD | Q24: Buy | R24: Amazon B0BTJTXHNN | S24: CNC build | U24: =IF(AND($K24="Y",$F24<>"Y",OR($T24="",$T24=Summary!$C$11)),$C24*IF($H24<>"",$H24,$D24)*INDEX(Summary!$C$6:$C$8,MATCH($P24,Summary!$B$6:$B$8,0)),0) -> 185 | V24: =IF(AND($K24="Y",$F24<>"Y",OR($T24="",$T24=Summary!$C$11)),$C24*IF($H24<>"",$H24,$E24)*INDEX(Summary!$C$6:$C$8,MATCH($P24,Summary!$B$6:$B$8,0)),0) -> 185 | W24: Verified | X24: https://www.amazon.ca/dp/B0BTJTXHNN
A25: C21 | B25: Arduino UNO | C25: 1 | F25: Y | G25: N | I25: =IF(AND($K25="Y",$F25<>"Y",OR($T25="",$T25=Summary!$C$11)),$C25*IF($H25<>"",$H25,($D25+$E25)/2)*INDEX(Summary!$C$6:$C$8,MATCH($P25,Summary!$B$6:$B$8,0)),0) -> 0 | J25: Have | K25: Y | L25: CNC: Electronics | M25: Motion control | N25: Flash GRBL 1.1. | O25: ea | P25: CAD | Q25: Have | R25: — | S25: CNC build | U25: =IF(AND($K25="Y",$F25<>"Y",OR($T25="",$T25=Summary!$C$11)),$C25*IF($H25<>"",$H25,$D25)*INDEX(Summary!$C$6:$C$8,MATCH($P25,Summary!$B$6:$B$8,0)),0) -> 0 | V25: =IF(AND($K25="Y",$F25<>"Y",OR($T25="",$T25=Summary!$C$11)),$C25*IF($H25<>"",$H25,$E25)*INDEX(Summary!$C$6:$C$8,MATCH($P25,Summary!$B$6:$B$8,0)),0) -> 0 | W25: Notes
A26: C22 | B26: CNC Shield V3 (shield only, no stepsticks) | C26: 1 | F26: N | G26: N | I26: =IF(AND($K26="Y",$F26<>"Y",OR($T26="",$T26=Summary!$C$11)),$C26*IF($H26<>"",$H26,($D26+$E26)/2)*INDEX(Summary!$C$6:$C$8,MATCH($P26,Summary!$B$6:$B$8,0)),0) -> 0 | J26: Need | K26: Y | L26: CNC: Electronics | M26: Motion control | N26: TB6600 step/dir wired to the shield's driver sockets. | O26: ea | P26: CAD | Q26: Buy | R26: AliExpress 1005006478108991 | S26: CNC build | U26: =IF(AND($K26="Y",$F26<>"Y",OR($T26="",$T26=Summary!$C$11)),$C26*IF($H26<>"",$H26,$D26)*INDEX(Summary!$C$6:$C$8,MATCH($P26,Summary!$B$6:$B$8,0)),0) -> 0 | V26: =IF(AND($K26="Y",$F26<>"Y",OR($T26="",$T26=Summary!$C$11)),$C26*IF($H26<>"",$H26,$E26)*INDEX(Summary!$C$6:$C$8,MATCH($P26,Summary!$B$6:$B$8,0)),0) -> 0 | W26: Notes | X26: https://www.aliexpress.com/item/1005006478108991.html
A27: C23 | B27: Limit switch, micro / endstop | C27: 6 | F27: N | G27: N | I27: =IF(AND($K27="Y",$F27<>"Y",OR($T27="",$T27=Summary!$C$11)),$C27*IF($H27<>"",$H27,($D27+$E27)/2)*INDEX(Summary!$C$6:$C$8,MATCH($P27,Summary!$B$6:$B$8,0)),0) -> 0 | J27: Need | K27: Y | L27: CNC: Electronics | M27: Switches | N27: 2 per axis. 5-packs. | O27: ea | P27: CAD | Q27: Buy | R27: AliExpress 1005001599112235 | S27: CNC build | U27: =IF(AND($K27="Y",$F27<>"Y",OR($T27="",$T27=Summary!$C$11)),$C27*IF($H27<>"",$H27,$D27)*INDEX(Summary!$C$6:$C$8,MATCH($P27,Summary!$B$6:$B$8,0)),0) -> 0 | V27: =IF(AND($K27="Y",$F27<>"Y",OR($T27="",$T27=Summary!$C$11)),$C27*IF($H27<>"",$H27,$E27)*INDEX(Summary!$C$6:$C$8,MATCH($P27,Summary!$B$6:$B$8,0)),0) -> 0 | W27: Notes | X27: https://www.aliexpress.com/item/1005001599112235.html
A28: C24 | B28: E-stop button, NC | C28: 1 | F28: N | G28: N | I28: =IF(AND($K28="Y",$F28<>"Y",OR($T28="",$T28=Summary!$C$11)),$C28*IF($H28<>"",$H28,($D28+$E28)/2)*INDEX(Summary!$C$6:$C$8,MATCH($P28,Summary!$B$6:$B$8,0)),0) -> 0 | J28: Need | K28: Y | L28: CNC: Electronics | M28: Switches | O28: ea | P28: CAD | Q28: Buy | R28: AliExpress | S28: CNC build | U28: =IF(AND($K28="Y",$F28<>"Y",OR($T28="",$T28=Summary!$C$11)),$C28*IF($H28<>"",$H28,$D28)*INDEX(Summary!$C$6:$C$8,MATCH($P28,Summary!$B$6:$B$8,0)),0) -> 0 | V28: =IF(AND($K28="Y",$F28<>"Y",OR($T28="",$T28=Summary!$C$11)),$C28*IF($H28<>"",$H28,$E28)*INDEX(Summary!$C$6:$C$8,MATCH($P28,Summary!$B$6:$B$8,0)),0) -> 0 | W28: Notes
A29: C25 | B29: Shielded 4-wire cable, stepper motors | C29: 15 | F29: N | G29: N | I29: =IF(AND($K29="Y",$F29<>"Y",OR($T29="",$T29=Summary!$C$11)),$C29*IF($H29<>"",$H29,($D29+$E29)/2)*INDEX(Summary!$C$6:$C$8,MATCH($P29,Summary!$B$6:$B$8,0)),0) -> 0 | J29: Need | K29: Y | L29: CNC: Electronics | M29: Wiring | N29: Author used double-shielded; ground the shield at the box only. | O29: m | P29: CAD | Q29: Buy | R29: AliExpress | S29: CNC build | U29: =IF(AND($K29="Y",$F29<>"Y",OR($T29="",$T29=Summary!$C$11)),$C29*IF($H29<>"",$H29,$D29)*INDEX(Summary!$C$6:$C$8,MATCH($P29,Summary!$B$6:$B$8,0)),0) -> 0 | V29: =IF(AND($K29="Y",$F29<>"Y",OR($T29="",$T29=Summary!$C$11)),$C29*IF($H29<>"",$H29,$E29)*INDEX(Summary!$C$6:$C$8,MATCH($P29,Summary!$B$6:$B$8,0)),0) -> 0 | W29: Notes
A30: C26 | B30: Shielded 2-wire cable, limit switches | C30: 10 | F30: N | G30: N | I30: =IF(AND($K30="Y",$F30<>"Y",OR($T30="",$T30=Summary!$C$11)),$C30*IF($H30<>"",$H30,($D30+$E30)/2)*INDEX(Summary!$C$6:$C$8,MATCH($P30,Summary!$B$6:$B$8,0)),0) -> 0 | J30: Need | K30: Y | L30: CNC: Electronics | M30: Wiring | O30: m | P30: CAD | Q30: Buy | R30: AliExpress | S30: CNC build | U30: =IF(AND($K30="Y",$F30<>"Y",OR($T30="",$T30=Summary!$C$11)),$C30*IF($H30<>"",$H30,$D30)*INDEX(Summary!$C$6:$C$8,MATCH($P30,Summary!$B$6:$B$8,0)),0) -> 0 | V30: =IF(AND($K30="Y",$F30<>"Y",OR($T30="",$T30=Summary!$C$11)),$C30*IF($H30<>"",$H30,$E30)*INDEX(Summary!$C$6:$C$8,MATCH($P30,Summary!$B$6:$B$8,0)),0) -> 0 | W30: Notes
A31: C27 | B31: Drag chain 10x20 + end mounts | C31: 2 | F31: N | G31: N | I31: =IF(AND($K31="Y",$F31<>"Y",OR($T31="",$T31=Summary!$C$11)),$C31*IF($H31<>"",$H31,($D31+$E31)/2)*INDEX(Summary!$C$6:$C$8,MATCH($P31,Summary!$B$6:$B$8,0)),0) -> 0 | J31: Need | K31: Y | L31: CNC: Electronics | M31: Wiring | N31: X and Y runs. | O31: m | P31: CAD | Q31: Buy | R31: AliExpress | S31: CNC build | U31: =IF(AND($K31="Y",$F31<>"Y",OR($T31="",$T31=Summary!$C$11)),$C31*IF($H31<>"",$H31,$D31)*INDEX(Summary!$C$6:$C$8,MATCH($P31,Summary!$B$6:$B$8,0)),0) -> 0 | V31: =IF(AND($K31="Y",$F31<>"Y",OR($T31="",$T31=Summary!$C$11)),$C31*IF($H31<>"",$H31,$E31)*INDEX(Summary!$C$6:$C$8,MATCH($P31,Summary!$B$6:$B$8,0)),0) -> 0 | W31: Notes
A32: C28 | B32: Terminal blocks, ferrules, USB cable, hookup wire | C32: 1 | F32: N | G32: N | I32: =IF(AND($K32="Y",$F32<>"Y",OR($T32="",$T32=Summary!$C$11)),$C32*IF($H32<>"",$H32,($D32+$E32)/2)*INDEX(Summary!$C$6:$C$8,MATCH($P32,Summary!$B$6:$B$8,0)),0) -> 0 | J32: Need | K32: Y | L32: CNC: Electronics | M32: Wiring | O32: lot | P32: CAD | Q32: Buy | R32: Amazon / AliExpress | S32: CNC build | U32: =IF(AND($K32="Y",$F32<>"Y",OR($T32="",$T32=Summary!$C$11)),$C32*IF($H32<>"",$H32,$D32)*INDEX(Summary!$C$6:$C$8,MATCH($P32,Summary!$B$6:$B$8,0)),0) -> 0 | V32: =IF(AND($K32="Y",$F32<>"Y",OR($T32="",$T32=Summary!$C$11)),$C32*IF($H32<>"",$H32,$E32)*INDEX(Summary!$C$6:$C$8,MATCH($P32,Summary!$B$6:$B$8,0)),0) -> 0 | W32: Notes
A33: C29 | B33: Electronics mounting panel (plywood) — enclosure optional | C33: 1 | F33: N | G33: N | I33: =IF(AND($K33="Y",$F33<>"Y",OR($T33="",$T33=Summary!$C$11)),$C33*IF($H33<>"",$H33,($D33+$E33)/2)*INDEX(Summary!$C$6:$C$8,MATCH($P33,Summary!$B$6:$B$8,0)),0) -> 0 | J33: Optional | K33: Y | L33: CNC: Electronics | M33: Control box | N33: Author's metal enclosure + GX16 connectors cost ~US$500; an open panel does the job. | O33: ea | P33: CAD | Q33: Make | R33: — | S33: CNC build | U33: =IF(AND($K33="Y",$F33<>"Y",OR($T33="",$T33=Summary!$C$11)),$C33*IF($H33<>"",$H33,$D33)*INDEX(Summary!$C$6:$C$8,MATCH($P33,Summary!$B$6:$B$8,0)),0) -> 0 | V33: =IF(AND($K33="Y",$F33<>"Y",OR($T33="",$T33=Summary!$C$11)),$C33*IF($H33<>"",$H33,$E33)*INDEX(Summary!$C$6:$C$8,MATCH($P33,Summary!$B$6:$B$8,0)),0) -> 0 | W33: Notes
